Workbook

Sheet Raw_Data
A1: Month | B1: Date | C1: SKU_ID | D1: Product_Name | E1: Category | F1: Units_Sold | G1: Unit_Price | H1: Promo_Flag
A2: 1 | B2: 44927 | C2: SKU001 | D2: Wireless Mouse | E2: Electronics | F2: 245 | G2: 25.99 | H2: 0
C3: SKU002 | D3: USB Cable | E3: Accessories | F3: 532 | G3: 8.99 | H3: 0
C4: SKU003 | D4: Laptop Stand | E4: Accessories | F4: 123 | G4: 45.99 | H4: 0
A5: 2 | B5: 44958 | C5: SKU001 | D5: Wireless Mouse | E5: Electronics | F5: 268 | G5: 25.99 | H5: 0
C6: SKU002 | D6: USB Cable | E6: Accessories | F6: 548 | G6: 8.99 | H6: 0
C7: SKU003 | D7: Laptop Stand | E7: Accessories | F7: 134 | G7: 45.99 | H7: 0
A8: 3 | B8: 44986 | C8: SKU001 | D8: Wireless Mouse | E8: Electronics | F8: 312 | G8: 25.99 | H8: 1
C9: SKU002 | D9: USB Cable | E9: Accessories | F9: 589 | G9: 8.99 | H9: 1
C10: SKU003 | D10: Laptop Stand | E10: Accessories | F10: 156 | G10: 45.99 | H10: 1
A11: 4 | B11: 45017 | C11: SKU001 | D11: Wireless Mouse | E11: Electronics | F11: 287 | G11: 25.99 | H11: 0
C12: SKU002 | D12: USB Cable | E12: Accessories | F12: 545 | G12: 8.99 | H12: 0
C13: SKU003 | D13: Laptop Stand | E13: Accessories | F13: 142 | G13: 45.99 | H13: 0
A14: 5 | B14: 45047 | C14: SKU001 | D14: Wireless Mouse | E14: Electronics | F14: 295 | G14: 25.99 | H14: 0
C15: SKU002 | D15: USB Cable | E15: Accessories | F15: 567 | G15: 8.99 | H15: 0
C16: SKU003 | D16: Laptop Stand | E16: Accessories | F16: 148 | G16: 45.99 | H16: 0
A17: 6 | B17: 45078 | C17: SKU001 | D17: Wireless Mouse | E17: Electronics | F17: 278 | G17: 25.99 | H17: 0
C18: SKU002 | D18: USB Cable | E18: Accessories | F18: 534 | G18: 8.99 | H18: 0
C19: SKU003 | D19: Laptop Stand | E19: Accessories | F19: 138 | G19: 45.99 | H19: 0
A20: 7 | B20: 45108 | C20: SKU001 | D20: Wireless Mouse | E20: Electronics | F20: 265 | G20: 25.99 | H20: 0
C21: SKU002 | D21: USB Cable | E21: Accessories | F21: 521 | G21: 8.99 | H21: 0
C22: SKU003 | D22: Laptop Stand | E22: Accessories | F22: 131 | G22: 45.99 | H22: 0
A23: 8 | B23: 45139 | C23: SKU001 | D23: Wireless Mouse | E23: Electronics | F23: 289 | G23: 25.99 | H23: 0
C24: SKU002 | D24: USB Cable | E24: Accessories | F24: 556 | G24: 8.99 | H24: 0
C25: SKU003 | D25: Laptop Stand | E25: Accessories | F25: 145 | G25: 45.99 | H25: 0
A26: 9 | B26: 45170 | C26: SKU001 | D26: Wireless Mouse | E26: Electronics | F26: 334 | G26: 25.99 | H26: 1
C27: SKU002 | D27: USB Cable | E27: Accessories | F27: 612 | G27: 8.99 | H27: 1
C28: SKU003 | D28: Laptop Stand | E28: Accessories | F28: 167 | G28: 45.99 | H28: 1
A29: 10 | B29: 45200 | C29: SKU001 | D29: Wireless Mouse | E29: Electronics | F29: 356 | G29: 25.99 | H29: 0
C30: SKU002 | D30: USB Cable | E30: Accessories | F30: 634 | G30: 8.99 | H30: 0
C31: SKU003 | D31: Laptop Stand | E31: Accessories | F31: 178 | G31: 45.99 | H31: 0
A32: 11 | B32: 45231 | C32: SKU001 | D32: Wireless Mouse | E32: Electronics | F32: 425 | G32: 25.99 | H32: 1
C33: SKU002 | D33: USB Cable | E33: Accessories | F33: 723 | G33: 8.99 | H33: 1
C34: SKU003 | D34: Laptop Stand | E34: Accessories | F34: 212 | G34: 45.99 | H34: 1
A35: 12 | B35: 45261 | C35: SKU001 | D35: Wireless Mouse | E35: Electronics | F35: 478 | G35: 25.99 | H35: 1
C36: SKU002 | D36: USB Cable | E36: Accessories | F36: 798 | G36: 8.99 | H36: 1
C37: SKU003 | D37: Laptop Stand | E37: Accessories | F37: 245 | G37: 45.99 | H37: 1
A38: 13 | B38: 45292 | C38: SKU001 | D38: Wireless Mouse | E38: Electronics | F38: 267 | G38: 26.99 | H38: 0
C39: SKU002 | D39: USB Cable | E39: Accessories | F39: 558 | G39: 9.49 | H39: 0
C40: SKU003 | D40: Laptop Stand | E40: Accessories | F40: 132 | G40: 47.99 | H40: 0
...

Sheet Forecast_Model
A1: Month | B1: Date | C1: Actual_Sales(SKU001) | D1: 3M_MA(SKU001) | E1: 6M_MA(SKU001) | F1: WMA(SKU001) | G1: Exp_Smooth(SKU001) | H1: Linear_Reg(SKU001) | I1: Best_Forecast(SKU001) | J1: Actual_Sales(SKU002) | K1: 3M_MA(SKU002) | L1: 6M_MA(SKU002) | M1: WMA(SKU002) | N1: Exp_Smooth(SKU002) | O1: Linear_Reg(SKU002) | P1: Best_Forecast(SKU002) | Q1: Actual_Sales(SKU003) | R1: 3M_MA(SKU003) | S1: 6M_MA(SKU003) | T1: WMA(SKU003) | U1: Exp_Smooth(SKU003) | V1: Linear_Reg(SKU003) | W1: Best_Forecast(SKU003)
A2: 1 | B2: 44927 | C2: 245 | G2: =C2 -> 245 | H2: =FORECAST(A2,$C$2:$C$24,$A$2:$A$24) -> 278.3587 | I2: =INDEX(D2:H2,MATCH(MIN(ABS(C2-D2),ABS(C2-E2),ABS(C2-F2),ABS(C2-G2),ABS(C2-H2),ABS(C2-D2:H2)),0)) | J2: 532 | N2: =J2 -> 532 | O2: =FORECAST(A2,$J$2:$J$24,$A$2:$A$24) -> 550.48913 | P2: =INDEX(K2:O2,MATCH(MIN(ABS(J2-K2),ABS(J2-L2),ABS(J2-M2),ABS(J2-N2),ABS(J2-O2),ABS(J2-K2:O2)),0)) | Q2: 123 | U2: =Q2 -> 123 | V2: =FORECAST(A2,$Q$2:$Q$24,$A$2:$A$24) -> 139 | W2: =INDEX(R2:V2,MATCH(MIN(ABS(Q2-R2),ABS(Q2-S2),ABS(Q2-T2),ABS(Q2-U2),ABS(Q2-V2),ABS(Q2-R2:V2)),0))
A3: 2 | B3: 44958 | C3: 268 | G3: =B28*C3+(1-B28)*G2 -> 251.9 | H3: =FORECAST(A3,$C$2:$C$24,$A$2:$A$24) -> 282.40514 | I3: =INDEX(D3:H3,MATCH(MIN(ABS(C3-D3),ABS(C3-E3),ABS(C3-F3),ABS(C3-G3),ABS(C3-H3),ABS(C3-D3:H3)),0)) | J3: 548 | N3: =$B$28*J3+(1-$B$28)*N2 -> 536.8 | O3: =FORECAST(A3,$J$2:$J$24,$A$2:$A$24) -> 555.12451 | P3: =INDEX(K3:O3,MATCH(MIN(ABS(J3-K3),ABS(J3-L3),ABS(J3-M3),ABS(J3-N3),ABS(J3-O3),ABS(J3-K3:O3)),0)) | Q3: 134 | U3: =$B$28*Q3+(1-$B$28)*U2 -> 126.3 | V3: =FORECAST(A3,$Q$2:$Q$24,$A$2:$A$24) -> 141.06324 | W3: =INDEX(R3:V3,MATCH(MIN(ABS(Q3-R3),ABS(Q3-S3),ABS(Q3-T3),ABS(Q3-U3),ABS(Q3-V3),ABS(Q3-R3:V3)),0))
A4: 3 | B4: 44986 | C4: 312 | G4: =$B$28*C4+(1-$B$28)*G3 -> 269.93 | H4: =FORECAST(A4,$C$2:$C$24,$A$2:$A$24) -> 286.45158 | I4: =INDEX(D4:H4,MATCH(MIN(ABS(C4-D4),ABS(C4-E4),ABS(C4-F4),ABS(C4-G4),ABS(C4-H4),ABS(C4-D4:H4)),0)) | J4: 589 | N4: =$B$28*J4+(1-$B$28)*N3 -> 552.46 | O4: =FORECAST(A4,$J$2:$J$24,$A$2:$A$24) -> 559.75988 | P4: =INDEX(K4:O4,MATCH(MIN(ABS(J4-K4),ABS(J4-L4),ABS(J4-M4),ABS(J4-N4),ABS(J4-O4),ABS(J4-K4:O4)),0)) | Q4: 156 | U4: =$B$28*Q4+(1-$B$28)*U3 -> 135.21 | V4: =FORECAST(A4,$Q$2:$Q$24,$A$2:$A$24) -> 143.12648 | W4: =INDEX(R4:V4,MATCH(MIN(ABS(Q4-R4),ABS(Q4-S4),ABS(Q4-T4),ABS(Q4-U4),ABS(Q4-V4),ABS(Q4-R4:V4)),0))
A5: 4 | B5: 45017 | C5: 287 | D5: =AVERAGE(C2:C4) -> 275 | F5: =(C4*0.5)+(C3*0.3)+(C2*0.2) -> 285.4 | G5: =$B$28*C5+(1-$B$28)*G4 -> 275.051 | H5: =FORECAST(A5,$C$2:$C$24,$A$2:$A$24) -> 290.49802 | I5: =INDEX(D5:H5,MATCH(MIN(ABS(C5-D5),ABS(C5-E5),ABS(C5-F5),ABS(C5-G5),ABS(C5-H5),ABS(C5-D5:H5)),0)) -> 275 | J5: 545 | K5: =AVERAGE(J2:J4) -> 556.33333 | M5: =(J4*0.5)+(J3*0.3)+(J2*0.2) -> 565.3 | N5: =$B$28*J5+(1-$B$28)*N4 -> 550.222 | O5: =FORECAST(A5,$J$2:$J$24,$A$2:$A$24) -> 564.39526 | P5: =INDEX(K5:O5,MATCH(MIN(ABS(J5-K5),ABS(J5-L5),ABS(J5-M5),ABS(J5-N5),ABS(J5-O5),ABS(J5-K5:O5)),0)) -> 556.33333 | Q5: 142 | R5: =AVERAGE(Q2:Q4) -> 137.66667 | T5: =(Q4*0.5)+(Q3*0.3)+(Q2*0.2) -> 142.8 | U5: =$B$28*Q5+(1-$B$28)*U4 -> 137.247 | V5: =FORECAST(A5,$Q$2:$Q$24,$A$2:$A$24) -> 145.18972 | W5: =INDEX(R5:V5,MATCH(MIN(ABS(Q5-R5),ABS(Q5-S5),ABS(Q5-T5),ABS(Q5-U5),ABS(Q5-V5),ABS(Q5-R5:V5)),0)) -> 137.66667
A6: 5 | B6: 45047 | C6: 295 | D6: =AVERAGE(C3:C5) -> 289 | F6: =(C5*0.5)+(C4*0.3)+(C3*0.2) -> 290.7 | G6: =$B$28*C6+(1-$B$28)*G5 -> 281.0357 | H6: =FORECAST(A6,$C$2:$C$24,$A$2:$A$24) -> 294.54447 | I6: =INDEX(D6:H6,MATCH(MIN(ABS(C6-D6),ABS(C6-E6),ABS(C6-F6),ABS(C6-G6),ABS(C6-H6),ABS(C6-D6:H6)),0)) -> 289 | J6: 567 | K6: =AVERAGE(J3:J5) -> 560.66667 | M6: =(J5*0.5)+(J4*0.3)+(J3*0.2) -> 558.8 | N6: =$B$28*J6+(1-$B$28)*N5 -> 555.2554 | O6: =FORECAST(A6,$J$2:$J$24,$A$2:$A$24) -> 569.03063 | P6: =INDEX(K6:O6,MATCH(MIN(ABS(J6-K6),ABS(J6-L6),ABS(J6-M6),ABS(J6-N6),ABS(J6-O6),ABS(J6-K6:O6)),0)) -> 560.66667 | Q6: 148 | R6: =AVERAGE(Q3:Q5) -> 144 | T6: =(Q5*0.5)+(Q4*0.3)+(Q3*0.2) -> 144.6 | U6: =$B$28*Q6+(1-$B$28)*U5 -> 140.4729 | V6: =FORECAST(A6,$Q$2:$Q$24,$A$2:$A$24) -> 147.25296 | W6: =INDEX(R6:V6,MATCH(MIN(ABS(Q6-R6),ABS(Q6-S6),ABS(Q6-T6),ABS(Q6-U6),ABS(Q6-V6),ABS(Q6-R6:V6)),0)) -> 144
A7: 6 | B7: 45078 | C7: 278 | D7: =AVERAGE(C4:C6) -> 298 | F7: =(C6*0.5)+(C5*0.3)+(C4*0.2) -> 296 | G7: =$B$28*C7+(1-$B$28)*G6 -> 280.12499 | H7: =FORECAST(A7,$C$2:$C$24,$A$2:$A$24) -> 298.59091 | I7: =INDEX(D7:H7,MATCH(MIN(ABS(C7-D7),ABS(C7-E7),ABS(C7-F7),ABS(C7-G7),ABS(C7-H7),ABS(C7-D7:H7)),0)) -> 298 | J7: 534 | K7: =AVERAGE(J4:J6) -> 567 | M7: =(J6*0.5)+(J5*0.3)+(J4*0.2) -> 564.8 | N7: =$B$28*J7+(1-$B$28)*N6 -> 548.87878 | O7: =FORECAST(A7,$J$2:$J$24,$A$2:$A$24) -> 573.66601 | P7: =INDEX(K7:O7,MATCH(MIN(ABS(J7-K7),ABS(J7-L7),ABS(J7-M7),ABS(J7-N7),ABS(J7-O7),ABS(J7-K7:O7)),0)) -> 567 | Q7: 138 | R7: =AVERAGE(Q4:Q6) -> 148.66667 | T7: =(Q6*0.5)+(Q5*0.3)+(Q4*0.2) -> 147.8 | U7: =$B$28*Q7+(1-$B$28)*U6 -> 139.73103 | V7: =FORECAST(A7,$Q$2:$Q$24,$A$2:$A$24) -> 149.31621 | W7: =INDEX(R7:V7,MATCH(MIN(ABS(Q7-R7),ABS(Q7-S7),ABS(Q7-T7),ABS(Q7-U7),ABS(Q7-V7),ABS(Q7-R7:V7)),0)) -> 148.66667
A8: 7 | B8: 45108 | C8: 265 | D8: =AVERAGE(C5:C7) -> 286.66667 | E8: =AVERAGE(C2:C7) -> 280.83333 | F8: =(C7*0.5)+(C6*0.3)+(C5*0.2) -> 284.9 | G8: =$B$28*C8+(1-$B$28)*G7 -> 275.58749 | H8: =FORECAST(A8,$C$2:$C$24,$A$2:$A$24) -> 302.63735 | I8: =INDEX(D8:H8,MATCH(MIN(ABS(C8-D8),ABS(C8-E8),ABS(C8-F8),ABS(C8-G8),ABS(C8-H8),ABS(C8-D8:H8)),0)) -> 286.66667 | J8: 521 | K8: =AVERAGE(J5:J7) -> 548.66667 | L8: =AVERAGE(J2:J7) -> 552.5 | M8: =(J7*0.5)+(J6*0.3)+(J5*0.2) -> 546.1 | N8: =$B$28*J8+(1-$B$28)*N7 -> 540.51515 | O8: =FORECAST(A8,$J$2:$J$24,$A$2:$A$24) -> 578.30138 | P8: =INDEX(K8:O8,MATCH(MIN(ABS(J8-K8),ABS(J8-L8),ABS(J8-M8),ABS(J8-N8),ABS(J8-O8),ABS(J8-K8:O8)),0)) -> 548.66667 | Q8: 131 | R8: =AVERAGE(Q5:Q7) -> 142.66667 | S8: =AVERAGE(Q2:Q7) -> 140.16667 | T8: =(Q7*0.5)+(Q6*0.3)+(Q5*0.2) -> 141.8 | U8: =$B$28*Q8+(1-$B$28)*U7 -> 137.11172 | V8: =FORECAST(A8,$Q$2:$Q$24,$A$2:$A$24) -> 151.37945 | W8: =INDEX(R8:V8,MATCH(MIN(ABS(Q8-R8),ABS(Q8-S8),ABS(Q8-T8),ABS(Q8-U8),ABS(Q8-V8),ABS(Q8-R8:V8)),0)) -> 142.66667
A9: 8 | B9: 45139 | C9: 289 | D9: =AVERAGE(C6:C8) -> 279.33333 | E9: =AVERAGE(C3:C8) -> 284.16667 | F9: =(C8*0.5)+(C7*0.3)+(C6*0.2) -> 274.9 | G9: =$B$28*C9+(1-$B$28)*G8 -> 279.61125 | H9: =FORECAST(A9,$C$2:$C$24,$A$2:$A$24) -> 306.68379 | I9: =INDEX(D9:H9,MATCH(MIN(ABS(C9-D9),ABS(C9-E9),ABS(C9-F9),ABS(C9-G9),ABS(C9-H9),ABS(C9-D9:H9)),0)) -> 279.33333 | J9: 556 | K9: =AVERAGE(J6:J8) -> 540.66667 | L9: =AVERAGE(J3:J8) -> 550.66667 | M9: =(J8*0.5)+(J7*0.3)+(J6*0.2) -> 534.1 | N9: =$B$28*J9+(1-$B$28)*N8 -> 545.1606 | O9: =FORECAST(A9,$J$2:$J$24,$A$2:$A$24) -> 582.93676 | P9: =INDEX(K9:O9,MATCH(MIN(ABS(J9-K9),ABS(J9-L9),ABS(J9-M9),ABS(J9-N9),ABS(J9-O9),ABS(J9-K9:O9)),0)) -> 540.66667 | Q9: 145 | R9: =AVERAGE(Q6:Q8) -> 139 | S9: =AVERAGE(Q3:Q8) -> 141.5 | T9: =(Q8*0.5)+(Q7*0.3)+(Q6*0.2) -> 136.5 | U9: =$B$28*Q9+(1-$B$28)*U8 -> 139.4782 | V9: =FORECAST(A9,$Q$2:$Q$24,$A$2:$A$24) -> 153.44269 | W9: =INDEX(R9:V9,MATCH(MIN(ABS(Q9-R9),ABS(Q9-S9),ABS(Q9-T9),ABS(Q9-U9),ABS(Q9-V9),ABS(Q9-R9:V9)),0)) -> 139
A10: 9 | B10: 45170 | C10: 334 | D10: =AVERAGE(C7:C9) -> 277.33333 | E10: =AVERAGE(C4:C9) -> 287.66667 | F10: =(C9*0.5)+(C8*0.3)+(C7*0.2) -> 279.6 | G10: =$B$28*C10+(1-$B$28)*G9 -> 295.92787 | H10: =FORECAST(A10,$C$2:$C$24,$A$2:$A$24) -> 310.73024 | I10: =INDEX(D10:H10,MATCH(MIN(ABS(C10-D10),ABS(C10-E10),ABS(C10-F10),ABS(C10-G10),ABS(C10-H10),ABS(C10-D10:H10)),0)) -> 277.33333 | J10: 612 | K10: =AVERAGE(J7:J9) -> 537 | L10: =AVERAGE(J4:J9) -> 552 | M10: =(J9*0.5)+(J8*0.3)+(J7*0.2) -> 541.1 | N10: =$B$28*J10+(1-$B$28)*N9 -> 565.21242 | O10: =FORECAST(A10,$J$2:$J$24,$A$2:$A$24) -> 587.57213 | P10: =INDEX(K10:O10,MATCH(MIN(ABS(J10-K10),ABS(J10-L10),ABS(J10-M10),ABS(J10-N10),ABS(J10-O10),ABS(J10-K10:O10)),0)) -> 537 | Q10: 167 | R10: =AVERAGE(Q7:Q9) -> 138 | S10: =AVERAGE(Q4:Q9) -> 143.33333 | T10: =(Q9*0.5)+(Q8*0.3)+(Q7*0.2) -> 139.4 | U10: =$B$28*Q10+(1-$B$28)*U9 -> 147.73474 | V10: =FORECAST(A10,$Q$2:$Q$24,$A$2:$A$24) -> 155.50593 | W10: =INDEX(R10:V10,MATCH(MIN(ABS(Q10-R10),ABS(Q10-S10),ABS(Q10-T10),ABS(Q10-U10),ABS(Q10-V10),ABS(Q10-R10:V10)),0)) -> 138
A11: 10 | B11: 45200 | C11: 356 | D11: =AVERAGE(C8:C10) -> 296 | E11: =AVERAGE(C5:C10) -> 291.33333 | F11: =(C10*0.5)+(C9*0.3)+(C8*0.2) -> 306.7 | G11: =$B$28*C11+(1-$B$28)*G10 -> 313.94951 | H11: =FORECAST(A11,$C$2:$C$24,$A$2:$A$24) -> 314.77668 | I11: =INDEX(D11:H11,MATCH(MIN(ABS(C11-D11),ABS(C11-E11),ABS(C11-F11),ABS(C11-G11),ABS(C11-H11),ABS(C11-D11:H11)),0)) -> 296 | J11: 634 | K11: =AVERAGE(J8:J10) -> 563 | L11: =AVERAGE(J5:J10) -> 555.83333 | M11: =(J10*0.5)+(J9*0.3)+(J8*0.2) -> 577 | N11: =$B$28*J11+(1-$B$28)*N10 -> 585.8487 | O11: =FORECAST(A11,$J$2:$J$24,$A$2:$A$24) -> 592.20751 | P11: =INDEX(K11:O11,MATCH(MIN(ABS(J11-K11),ABS(J11-L11),ABS(J11-M11),ABS(J11-N11),ABS(J11-O11),ABS(J11-K11:O11)),0)) -> 563 | Q11: 178 | R11: =AVERAGE(Q8:Q10) -> 147.66667 | S11: =AVERAGE(Q5:Q10) -> 145.16667 | T11: =(Q10*0.5)+(Q9*0.3)+(Q8*0.2) -> 153.2 | U11: =$B$28*Q11+(1-$B$28)*U10 -> 156.81432 | V11: =FORECAST(A11,$Q$2:$Q$24,$A$2:$A$24) -> 157.56917 | W11: =INDEX(R11:V11,MATCH(MIN(ABS(Q11-R11),ABS(Q11-S11),ABS(Q11-T11),ABS(Q11-U11),ABS(Q11-V11),ABS(Q11-R11:V11)),0)) -> 147.66667
A12: 11 | B12: 45231 | C12: 425 | D12: =AVERAGE(C9:C11) -> 326.33333 | E12: =AVERAGE(C6:C11) -> 302.83333 | F12: =(C11*0.5)+(C10*0.3)+(C9*0.2) -> 336 | G12: =$B$28*C12+(1-$B$28)*G11 -> 347.26466 | H12: =FORECAST(A12,$C$2:$C$24,$A$2:$A$24) -> 318.82312 | I12: =INDEX(D12:H12,MATCH(MIN(ABS(C12-D12),ABS(C12-E12),ABS(C12-F12),ABS(C12-G12),ABS(C12-H12),ABS(C12-D12:H12)),0)) -> 326.33333 | J12: 723 | K12: =AVERAGE(J9:J11) -> 600.66667 | L12: =AVERAGE(J6:J11) -> 570.66667 | M12: =(J11*0.5)+(J10*0.3)+(J9*0.2) -> 611.8 | N12: =$B$28*J12+(1-$B$28)*N11 -> 626.99409 | O12: =FORECAST(A12,$J$2:$J$24,$A$2:$A$24) -> 596.84289 | P12: =INDEX(K12:O12,MATCH(MIN(ABS(J12-K12),ABS(J12-L12),ABS(J12-M12),ABS(J12-N12),ABS(J12-O12),ABS(J12-K12:O12)),0)) -> 600.66667 | Q12: 212 | R12: =AVERAGE(Q9:Q11) -> 163.33333 | S12: =AVERAGE(Q6:Q11) -> 151.16667 | T12: =(Q11*0.5)+(Q10*0.3)+(Q9*0.2) -> 168.1 | U12: =$B$28*Q12+(1-$B$28)*U11 -> 173.37002 | V12: =FORECAST(A12,$Q$2:$Q$24,$A$2:$A$24) -> 159.63241 | W12: =INDEX(R12:V12,MATCH(MIN(ABS(Q12-R12),ABS(Q12-S12),ABS(Q12-T12),ABS(Q12-U12),ABS(Q12-V12),ABS(Q12-R12:V12)),0)) -> 163.33333
A13: 12 | B13: 45261 | C13: 478 | D13: =AVERAGE(C10:C12) -> 371.66667 | E13: =AVERAGE(C7:C12) -> 324.5 | F13: =(C12*0.5)+(C11*0.3)+(C10*0.2) -> 386.1 | G13: =$B$28*C13+(1-$B$28)*G12 -> 386.48526 | H13: =FORECAST(A13,$C$2:$C$24,$A$2:$A$24) -> 322.86957 | I13: =INDEX(D13:H13,MATCH(MIN(ABS(C13-D13),ABS(C13-E13),ABS(C13-F13),ABS(C13-G13),ABS(C13-H13),ABS(C13-D13:H13)),0)) -> 371.66667 | J13: 798 | K13: =AVERAGE(J10:J12) -> 656.33333 | L13: =AVERAGE(J7:J12) -> 596.66667 | M13: =(J12*0.5)+(J11*0.3)+(J10*0.2) -> 674.1 | N13: =$B$28*J13+(1-$B$28)*N12 -> 678.29586 | O13: =FORECAST(A13,$J$2:$J$24,$A$2:$A$24) -> 601.47826 | P13: =INDEX(K13:O13,MATCH(MIN(ABS(J13-K13),ABS(J13-L13),ABS(J13-M13),ABS(J13-N13),ABS(J13-O13),ABS(J13-K13:O13)),0)) -> 656.33333 | Q13: 245 | R13: =AVERAGE(Q10:Q12) -> 185.66667 | S13: =AVERAGE(Q7:Q12) -> 161.83333 | T13: =(Q12*0.5)+(Q11*0.3)+(Q10*0.2) -> 192.8 | U13: =$B$28*Q13+(1-$B$28)*U12 -> 194.85902 | V13: =FORECAST(A13,$Q$2:$Q$24,$A$2:$A$24) -> 161.69565 | W13: =INDEX(R13:V13,MATCH(MIN(ABS(Q13-R13),ABS(Q13-S13),ABS(Q13-T13),ABS(Q13-U13),ABS(Q13-V13),ABS(Q13-R13:V13)),0)) -> 185.66667
A14: 13 | B14: 45292 | C14: 267 | D14: =AVERAGE(C11:C13) -> 419.66667 | E14: =AVERAGE(C8:C13) -> 357.83333 | F14: =(C13*0.5)+(C12*0.3)+(C11*0.2) -> 437.7 | G14: =$B$28*C14+(1-$B$28)*G13 -> 350.63968 | H14: =FORECAST(A14,$C$2:$C$24,$A$2:$A$24) -> 326.91601 | I14: =INDEX(D14:H14,MATCH(MIN(ABS(C14-D14),ABS(C14-E14),ABS(C14-F14),ABS(C14-G14),ABS(C14-H14),ABS(C14-D14:H14)),0)) -> 419.66667 | J14: 558 | K14: =AVERAGE(J11:J13) -> 718.33333 | L14: =AVERAGE(J8:J13) -> 640.66667 | M14: =(J13*0.5)+(J12*0.3)+(J11*0.2) -> 742.7 | N14: =$B$28*J14+(1-$B$28)*N13 -> 642.2071 | O14: =FORECAST(A14,$J$2:$J$24,$A$2:$A$24) -> 606.11364 | P14: =INDEX(K14:O14,MATCH(MIN(ABS(J14-K14),ABS(J14-L14),ABS(J14-M14),ABS(J14-N14),ABS(J14-O14),ABS(J14-K14:O14)),0)) -> 718.33333 | Q14: 132 | R14: =AVERAGE(Q11:Q13) -> 211.66667 | S14: =AVERAGE(Q8:Q13) -> 179.66667 | T14: =(Q13*0.5)+(Q12*0.3)+(Q11*0.2) -> 221.7 | U14: =$B$28*Q14+(1-$B$28)*U13 -> 176.00131 | V14: =FORECAST(A14,$Q$2:$Q$24,$A$2:$A$24) -> 163.75889 | W14: =INDEX(R14:V14,MATCH(MIN(ABS(Q14-R14),ABS(Q14-S14),ABS(Q14-T14),ABS(Q14-U14),ABS(Q14-V14),ABS(Q14-R14:V14)),0)) -> 211.66667
A15: 14 | B15: 45323 | C15: 285 | D15: =AVERAGE(C12:C14) -> 390 | E15: =AVERAGE(C9:C14) -> 358.16667 | F15: =(C14*0.5)+(C13*0.3)+(C12*0.2) -> 361.9 | G15: =$B$28*C15+(1-$B$28)*G14 -> 330.94778 | H15: =FORECAST(A15,$C$2:$C$24,$A$2:$A$24) -> 330.96245 | I15: =INDEX(D15:H15,MATCH(MIN(ABS(C15-D15),ABS(C15-E15),ABS(C15-F15),ABS(C15-G15),ABS(C15-H15),ABS(C15-D15:H15)),0)) -> 390 | J15: 572 | K15: =AVERAGE(J12:J14) -> 693 | L15: =AVERAGE(J9:J14) -> 646.83333 | M15: =(J14*0.5)+(J13*0.3)+(J12*0.2) -> 663 | N15: =$B$28*J15+(1-$B$28)*N14 -> 621.14497 | O15: =FORECAST(A15,$J$2:$J$24,$A$2:$A$24) -> 610.74901 | P15: =INDEX(K15:O15,MATCH(MIN(ABS(J15-K15),ABS(J15-L15),ABS(J15-M15),ABS(J15-N15),ABS(J15-O15),ABS(J15-K15:O15)),0)) -> 693 | Q15: 145 | R15: =AVERAGE(Q12:Q14) -> 196.33333 | S15: =AVERAGE(Q9:Q14) -> 179.83333 | T15: =(Q14*0.5)+(Q13*0.3)+(Q12*0.2) -> 181.9 | U15: =$B$28*Q15+(1-$B$28)*U14 -> 166.70092 | V15: =FORECAST(A15,$Q$2:$Q$24,$A$2:$A$24) -> 165.82213 | W15: =INDEX(R15:V15,MATCH(MIN(ABS(Q15-R15),ABS(Q15-S15),ABS(Q15-T15),ABS(Q15-U15),ABS(Q15-V15),ABS(Q15-R15:V15)),0)) -> 196.33333
A16: 15 | B16: 45352 | C16: 338 | D16: =AVERAGE(C13:C15) -> 343.33333 | E16: =AVERAGE(C10:C15) -> 357.5 | F16: =(C15*0.5)+(C14*0.3)+(C13*0.2) -> 318.2 | G16: =$B$28*C16+(1-$B$28)*G15 -> 333.06344 | H16: =FORECAST(A16,$C$2:$C$24,$A$2:$A$24) -> 335.00889 | I16: =INDEX(D16:H16,MATCH(MIN(ABS(C16-D16),ABS(C16-E16),ABS(C16-F16),ABS(C16-G16),ABS(C16-H16),ABS(C16-D16:H16)),0)) -> 343.33333 | J16: 618 | K16: =AVERAGE(J13:J15) -> 642.66667 | L16: =AVERAGE(J10:J15) -> 649.5 | M16: =(J15*0.5)+(J14*0.3)+(J13*0.2) -> 613 | N16: =$B$28*J16+(1-$B$28)*N15 -> 620.20148 | O16: =FORECAST(A16,$J$2:$J$24,$A$2:$A$24) -> 615.38439 | P16: =INDEX(K16:O16,MATCH(MIN(ABS(J16-K16),ABS(J16-L16),ABS(J16-M16),ABS(J16-N16),ABS(J16-O16),ABS(J16-K16:O16)),0)) -> 642.66667 | Q16: 168 | R16: =AVERAGE(Q13:Q15) -> 174 | S16: =AVERAGE(Q10:Q15) -> 179.83333 | T16: =(Q15*0.5)+(Q14*0.3)+(Q13*0.2) -> 161.1 | U16: =$B$28*Q16+(1-$B$28)*U15 -> 167.09064 | V16: =FORECAST(A16,$Q$2:$Q$24,$A$2:$A$24) -> 167.88538 | W16: =INDEX(R16:V16,MATCH(MIN(ABS(Q16-R16),ABS(Q16-S16),ABS(Q16-T16),ABS(Q16-U16),ABS(Q16-V16),ABS(Q16-R16:V16)),0)) -> 174
A17: 16 | B17: 45383 | C17: 305 | D17: =AVERAGE(C14:C16) -> 296.66667 | E17: =AVERAGE(C11:C16) -> 358.16667 | F17: =(C16*0.5)+(C15*0.3)+(C14*0.2) -> 307.9 | G17: =$B$28*C17+(1-$B$28)*G16 -> 324.64441 | H17: =FORECAST(A17,$C$2:$C$24,$A$2:$A$24) -> 339.05534 | I17: =INDEX(D17:H17,MATCH(MIN(ABS(C17-D17),ABS(C17-E17),ABS(C17-F17),ABS(C17-G17),ABS(C17-H17),ABS(C17-D17:H17)),0)) -> 296.66667 | J17: 573 | K17: =AVERAGE(J14:J16) -> 582.66667 | L17: =AVERAGE(J11:J16) -> 650.5 | M17: =(J16*0.5)+(J15*0.3)+(J14*0.2) -> 592.2 | N17: =$B$28*J17+(1-$B$28)*N16 -> 606.04104 | O17: =FORECAST(A17,$J$2:$J$24,$A$2:$A$24) -> 620.01976 | P17: =INDEX(K17:O17,MATCH(MIN(ABS(J17-K17),ABS(J17-L17),ABS(J17-M17),ABS(J17-N17),ABS(J17-O17),ABS(J17-K17:O17)),0)) -> 582.66667 | Q17: 153 | R17: =AVERAGE(Q14:Q16) -> 148.33333 | S17: =AVERAGE(Q11:Q16) -> 180 | T17: =(Q16*0.5)+(Q15*0.3)+(Q14*0.2) -> 153.9 | U17: =$B$28*Q17+(1-$B$28)*U16 -> 162.86345 | V17: =FORECAST(A17,$Q$2:$Q$24,$A$2:$A$24) -> 169.94862 | W17: =INDEX(R17:V17,MATCH(MIN(ABS(Q17-R17),ABS(Q17-S17),ABS(Q17-T17),ABS(Q17-U17),ABS(Q17-V17),ABS(Q17-R17:V17)),0)) -> 148.33333
A18: 17 | B18: 45413 | C18: 318 | D18: =AVERAGE(C15:C17) -> 309.33333 | E18: =AVERAGE(C12:C17) -> 349.66667 | F18: =(C17*0.5)+(C16*0.3)+(C15*0.2) -> 310.9 | G18: =$B$28*C18+(1-$B$28)*G17 -> 322.65109 | H18: =FORECAST(A18,$C$2:$C$24,$A$2:$A$24) -> 343.10178 | I18: =INDEX(D18:H18,MATCH(MIN(ABS(C18-D18),ABS(C18-E18),ABS(C18-F18),ABS(C18-G18),ABS(C18-H18),ABS(C18-D18:H18)),0)) -> 309.33333 | J18: 589 | K18: =AVERAGE(J15:J17) -> 587.66667 | L18: =AVERAGE(J12:J17) -> 640.33333 | M18: =(J17*0.5)+(J16*0.3)+(J15*0.2) -> 586.3 | N18: =$B$28*J18+(1-$B$28)*N17 -> 600.92873 | O18: =FORECAST(A18,$J$2:$J$24,$A$2:$A$24) -> 624.65514 | P18: =INDEX(K18:O18,MATCH(MIN(ABS(J18-K18),ABS(J18-L18),ABS(J18-M18),ABS(J18-N18),ABS(J18-O18),ABS(J18-K18:O18)),0)) -> 587.66667 | Q18: 159 | R18: =AVERAGE(Q15:Q17) -> 155.33333 | S18: =AVERAGE(Q12:Q17) -> 175.83333 | T18: =(Q17*0.5)+(Q16*0.3)+(Q15*0.2) -> 155.9 | U18: =$B$28*Q18+(1-$B$28)*U17 -> 161.70442 | V18: =FORECAST(A18,$Q$2:$Q$24,$A$2:$A$24) -> 172.01186 | W18: =INDEX(R18:V18,MATCH(MIN(ABS(Q18-R18),ABS(Q18-S18),ABS(Q18-T18),ABS(Q18-U18),ABS(Q18-V18),ABS(Q18-R18:V18)),0)) -> 155.33333
A19: 18 | B19: 45444 | C19: 295 | D19: =AVERAGE(C16:C18) -> 320.33333 | E19: =AVERAGE(C13:C18) -> 331.83333 | F19: =(C18*0.5)+(C17*0.3)+(C16*0.2) -> 318.1 | G19: =$B$28*C19+(1-$B$28)*G18 -> 314.35576 | H19: =FORECAST(A19,$C$2:$C$24,$A$2:$A$24) -> 347.14822 | I19: =INDEX(D19:H19,MATCH(MIN(ABS(C19-D19),ABS(C19-E19),ABS(C19-F19),ABS(C19-G19),ABS(C19-H19),ABS(C19-D19:H19)),0)) -> 320.33333 | J19: 561 | K19: =AVERAGE(J16:J18) -> 593.33333 | L19: =AVERAGE(J13:J18) -> 618 | M19: =(J18*0.5)+(J17*0.3)+(J16*0.2) -> 590 | N19: =$B$28*J19+(1-$B$28)*N18 -> 588.95011 | O19: =FORECAST(A19,$J$2:$J$24,$A$2:$A$24) -> 629.29051 | P19: =INDEX(K19:O19,MATCH(MIN(ABS(J19-K19),ABS(J19-L19),ABS(J19-M19),ABS(J19-N19),ABS(J19-O19),ABS(J19-K19:O19)),0)) -> 593.33333 | Q19: 147 | R19: =AVERAGE(Q16:Q18) -> 160 | S19: =AVERAGE(Q13:Q18) -> 167 | T19: =(Q18*0.5)+(Q17*0.3)+(Q16*0.2) -> 159 | U19: =$B$28*Q19+(1-$B$28)*U18 -> 157.29309 | V19: =FORECAST(A19,$Q$2:$Q$24,$A$2:$A$24) -> 174.0751 | W19: =INDEX(R19:V19,MATCH(MIN(ABS(Q19-R19),ABS(Q19-S19),ABS(Q19-T19),ABS(Q19-U19),ABS(Q19-V19),ABS(Q19-R19:V19)),0)) -> 160
... A25: 24 | B25: 45627 | C25: 512 | D25: =AVERAGE(C22:C24) -> 398.66667 | E25: =AVERAGE(C19:C24) -> 346.83333 | F25: =(C24*0.5)+(C23*0.3)+(C22*0.2) -> 414.2 | G25: =$B$28*C25+(1-$B$28)*G24 -> 415.7398 | H25: =FORECAST(A25,$C$2:$C$24,$A$2:$A$24) -> 371.42688 | I25: =INDEX(D25:H25,MATCH(MIN(ABS(C25-D25),ABS(C25-E25),ABS(C25-F25),ABS(C25-G25),ABS(C25-H25),ABS(C25-D25:H25)),0)) -> 398.66667 | J25: 834 | K25: =AVERAGE(J22:J24) -> 691.66667 | L25: =AVERAGE(J19:J24) -> 627.5 | M25: =(J24*0.5)+(J23*0.3)+(J22*0.2) -> 710.4 | N25: =$B$28*J25+(1-$B$28)*N24 -> 713.62086 | O25: =FORECAST(A25,$J$2:$J$24,$A$2:$A$24) -> 657.10277 | P25: =INDEX(K25:O25,MATCH(MIN(ABS(J25-K25),ABS(J25-L25),ABS(J25-M25),ABS(J25-N25),ABS(J25-O25),ABS(J25-K25:O25)),0)) -> 691.66667 | Q25: 263 | R25: =AVERAGE(Q22:Q24) -> 199.66667 | S25: =AVERAGE(Q19:Q24) -> 173.83333 | T25: =(Q24*0.5)+(Q23*0.3)+(Q22*0.2) -> 207.4 | U25: =$B$28*Q25+(1-$B$28)*U24 -> 210.27452 | V25: =FORECAST(A25,$Q$2:$Q$24,$A$2:$A$24) -> 186.45455 | W25: =INDEX(R25:V25,MATCH(MIN(ABS(Q25-R25),ABS(Q25-S25),ABS(Q25-T25),ABS(Q25-U25),ABS(Q25-V25),ABS(Q25-R25:V25)),0)) -> 199.66667
A28: Alpha | B28: 0.3

Sheet Accuracy_Metrics
A1: Month | B1: Actual(SKU001) | C1: 3M_MA_Error(SKU001) | D1: 6M_MA_Error(SKU001) | E1: WMA_Error(SKU001) | F1: Exp_Error(SKU001) | G1: Reg_Error(SKU001) | H1: Actual(SKU002) | I1: 3M_MA_Error(SKU002) | J1: 6M_MA_Error(SKU002) | K1: WMA_Error(SKU002) | L1: Exp_Error(SKU002) | M1: Reg_Error(SKU002) | N1: Actual(SKU003) | O1: 3M_MA_Error(SKU003) | P1: 6M_MA_Error(SKU003) | Q1: WMA_Error(SKU003) | R1: Exp_Error(SKU003) | S1: Reg_Error(SKU003)
A2: 1 | B2: 245 | F2: =ABS(Forecast_Model!J2-Forecast_Model!N2) -> 0 | G2: =ABS(Forecast_Model!C2-Forecast_Model!H2) -> 33.358696 | H2: 532 | L2: =ABS(Forecast_Model!J2-Forecast_Model!N2) -> 0 | M2: =ABS(Forecast_Model!J2-Forecast_Model!O2) -> 18.48913 | N2: 123 | R2: =ABS(Forecast_Model!Q2-Forecast_Model!U2) -> 0 | S2: =ABS(Forecast_Model!Q2-Forecast_Model!V2) -> 16
A3: 2 | B3: 268 | F3: =ABS(Forecast_Model!J3-Forecast_Model!N3) -> 11.2 | G3: =ABS(Forecast_Model!C3-Forecast_Model!H3) -> 14.405138 | H3: 548 | L3: =ABS(Forecast_Model!J3-Forecast_Model!N3) -> 11.2 | M3: =ABS(Forecast_Model!J3-Forecast_Model!O3) -> 7.1245059 | N3: 134 | R3: =ABS(Forecast_Model!Q3-Forecast_Model!U3) -> 7.7 | S3: =ABS(Forecast_Model!Q3-Forecast_Model!V3) -> 7.0632411
A4: 3 | B4: 312 | F4: =ABS(Forecast_Model!J4-Forecast_Model!N4) -> 36.54 | G4: =ABS(Forecast_Model!C4-Forecast_Model!H4) -> 25.548419 | H4: 589 | L4: =ABS(Forecast_Model!J4-Forecast_Model!N4) -> 36.54 | M4: =ABS(Forecast_Model!J4-Forecast_Model!O4) -> 29.240119 | N4: 156 | R4: =ABS(Forecast_Model!Q4-Forecast_Model!U4) -> 20.79 | S4: =ABS(Forecast_Model!Q4-Forecast_Model!V4) -> 12.873518
A5: 4 | B5: 287 | C5: =ABS(Forecast_Model!C5-Forecast_Model!D5) -> 12 | E5: =ABS(Forecast_Model!C5-Forecast_Model!F5) -> 1.6 | F5: =ABS(Forecast_Model!J5-Forecast_Model!N5) -> 5.222 | G5: =ABS(Forecast_Model!C5-Forecast_Model!H5) -> 3.4980237 | H5: 545 | I5: =ABS(Forecast_Model!J5-Forecast_Model!K5) -> 11.333333 | K5: =ABS(Forecast_Model!J5-Forecast_Model!M5) -> 20.3 | L5: =ABS(Forecast_Model!J5-Forecast_Model!N5) -> 5.222 | M5: =ABS(Forecast_Model!J5-Forecast_Model!O5) -> 19.395257 | N5: 142 | O5: =ABS(Forecast_Model!Q5-Forecast_Model!R5) -> 4.3333333 | Q5: =ABS(Forecast_Model!Q5-Forecast_Model!T5) -> 0.8 | R5: =ABS(Forecast_Model!Q5-Forecast_Model!U5) -> 4.753 | S5: =ABS(Forecast_Model!Q5-Forecast_Model!V5) -> 3.1897233
A6: 5 | B6: 295 | C6: =ABS(Forecast_Model!C6-Forecast_Model!D6) -> 6 | E6: =ABS(Forecast_Model!C6-Forecast_Model!F6) -> 4.3 | F6: =ABS(Forecast_Model!J6-Forecast_Model!N6) -> 11.7446 | G6: =ABS(Forecast_Model!C6-Forecast_Model!H6) -> 0.4555336 | H6: 567 | I6: =ABS(Forecast_Model!J6-Forecast_Model!K6) -> 6.3333333 | K6: =ABS(Forecast_Model!J6-Forecast_Model!M6) -> 8.2 | L6: =ABS(Forecast_Model!J6-Forecast_Model!N6) -> 11.7446 | M6: =ABS(Forecast_Model!J6-Forecast_Model!O6) -> 2.0306324 | N6: 148 | O6: =ABS(Forecast_Model!Q6-Forecast_Model!R6) -> 4 | Q6: =ABS(Forecast_Model!Q6-Forecast_Model!T6) -> 3.4 | R6: =ABS(Forecast_Model!Q6-Forecast_Model!U6) -> 7.5271 | S6: =ABS(Forecast_Model!Q6-Forecast_Model!V6) -> 0.74703557
A7: 6 | B7: 278 | C7: =ABS(Forecast_Model!C7-Forecast_Model!D7) -> 20 | E7: =ABS(Forecast_Model!C7-Forecast_Model!F7) -> 18 | F7: =ABS(Forecast_Model!J7-Forecast_Model!N7) -> 14.87878 | G7: =ABS(Forecast_Model!C7-Forecast_Model!H7) -> 20.590909 | H7: 534 | I7: =ABS(Forecast_Model!J7-Forecast_Model!K7) -> 33 | K7: =ABS(Forecast_Model!J7-Forecast_Model!M7) -> 30.8 | L7: =ABS(Forecast_Model!J7-Forecast_Model!N7) -> 14.87878 | M7: =ABS(Forecast_Model!J7-Forecast_Model!O7) -> 39.666008 | N7: 138 | O7: =ABS(Forecast_Model!Q7-Forecast_Model!R7) -> 10.666667 | Q7: =ABS(Forecast_Model!Q7-Forecast_Model!T7) -> 9.8 | R7: =ABS(Forecast_Model!Q7-Forecast_Model!U7) -> 1.73103 | S7: =ABS(Forecast_Model!Q7-Forecast_Model!V7) -> 11.316206
A8: 7 | B8: 265 | C8: =ABS(Forecast_Model!C8-Forecast_Model!D8) -> 21.666667 | D8: =ABS(Forecast_Model!C8-Forecast_Model!E8) -> 15.833333 | E8: =ABS(Forecast_Model!C8-Forecast_Model!F8) -> 19.9 | F8: =ABS(Forecast_Model!J8-Forecast_Model!N8) -> 19.515146 | G8: =ABS(Forecast_Model!C8-Forecast_Model!H8) -> 37.637352 | H8: 521 | I8: =ABS(Forecast_Model!J8-Forecast_Model!K8) -> 27.666667 | J8: =ABS(Forecast_Model!J8-Forecast_Model!L8) -> 31.5 | K8: =ABS(Forecast_Model!J8-Forecast_Model!M8) -> 25.1 | L8: =ABS(Forecast_Model!J8-Forecast_Model!N8) -> 19.515146 | M8: =ABS(Forecast_Model!J8-Forecast_Model!O8) -> 57.301383 | N8: 131 | O8: =ABS(Forecast_Model!Q8-Forecast_Model!R8) -> 11.666667 | P8: =ABS(Forecast_Model!Q8-Forecast_Model!S8) -> 9.1666667 | Q8: =ABS(Forecast_Model!Q8-Forecast_Model!T8) -> 10.8 | R8: =ABS(Forecast_Model!Q8-Forecast_Model!U8) -> 6.111721 | S8: =ABS(Forecast_Model!Q8-Forecast_Model!V8) -> 20.379447
A9: 8 | B9: 289 | C9: =ABS(Forecast_Model!C9-Forecast_Model!D9) -> 9.6666667 | D9: =ABS(Forecast_Model!C9-Forecast_Model!E9) -> 4.8333333 | E9: =ABS(Forecast_Model!C9-Forecast_Model!F9) -> 14.1 | F9: =ABS(Forecast_Model!J9-Forecast_Model!N9) -> 10.839398 | G9: =ABS(Forecast_Model!C9-Forecast_Model!H9) -> 17.683794 | H9: 556 | I9: =ABS(Forecast_Model!J9-Forecast_Model!K9) -> 15.333333 | J9: =ABS(Forecast_Model!J9-Forecast_Model!L9) -> 5.3333333 | K9: =ABS(Forecast_Model!J9-Forecast_Model!M9) -> 21.9 | L9: =ABS(Forecast_Model!J9-Forecast_Model!N9) -> 10.839398 | M9: =ABS(Forecast_Model!J9-Forecast_Model!O9) -> 26.936759 | N9: 145 | O9: =ABS(Forecast_Model!Q9-Forecast_Model!R9) -> 6 | P9: =ABS(Forecast_Model!Q9-Forecast_Model!S9) -> 3.5 | Q9: =ABS(Forecast_Model!Q9-Forecast_Model!T9) -> 8.5 | R9: =ABS(Forecast_Model!Q9-Forecast_Model!U9) -> 5.5217953 | S9: =ABS(Forecast_Model!Q9-Forecast_Model!V9) -> 8.4426877
A10: 9 | B10: 334 | C10: =ABS(Forecast_Model!C10-Forecast_Model!D10) -> 56.666667 | D10: =ABS(Forecast_Model!C10-Forecast_Model!E10) -> 46.333333 | E10: =ABS(Forecast_Model!C10-Forecast_Model!F10) -> 54.4 | F10: =ABS(Forecast_Model!J10-Forecast_Model!N10) -> 46.787578 | G10: =ABS(Forecast_Model!C10-Forecast_Model!H10) -> 23.269763 | H10: 612 | I10: =ABS(Forecast_Model!J10-Forecast_Model!K10) -> 75 | J10: =ABS(Forecast_Model!J10-Forecast_Model!L10) -> 60 | K10: =ABS(Forecast_Model!J10-Forecast_Model!M10) -> 70.9 | L10: =ABS(Forecast_Model!J10-Forecast_Model!N10) -> 46.787578 | M10: =ABS(Forecast_Model!J10-Forecast_Model!O10) -> 24.427866 | N10: 167 | O10: =ABS(Forecast_Model!Q10-Forecast_Model!R10) -> 29 | P10: =ABS(Forecast_Model!Q10-Forecast_Model!S10) -> 23.666667 | Q10: =ABS(Forecast_Model!Q10-Forecast_Model!T10) -> 27.6 | R10: =ABS(Forecast_Model!Q10-Forecast_Model!U10) -> 19.265257 | S10: =ABS(Forecast_Model!Q10-Forecast_Model!V10) -> 11.494071
A11: 10 | B11: 356 | C11: =ABS(Forecast_Model!C11-Forecast_Model!D11) -> 60 | D11: =ABS(Forecast_Model!C11-Forecast_Model!E11) -> 64.666667 | E11: =ABS(Forecast_Model!C11-Forecast_Model!F11) -> 49.3 | F11: =ABS(Forecast_Model!J11-Forecast_Model!N11) -> 48.151305 | G11: =ABS(Forecast_Model!C11-Forecast_Model!H11) -> 41.22332 | H11: 634 | I11: =ABS(Forecast_Model!J11-Forecast_Model!K11) -> 71 | J11: =ABS(Forecast_Model!J11-Forecast_Model!L11) -> 78.166667 | K11: =ABS(Forecast_Model!J11-Forecast_Model!M11) -> 57 | L11: =ABS(Forecast_Model!J11-Forecast_Model!N11) -> 48.151305 | M11: =ABS(Forecast_Model!J11-Forecast_Model!O11) -> 41.79249 | N11: 178 | O11: =ABS(Forecast_Model!Q11-Forecast_Model!R11) -> 30.333333 | P11: =ABS(Forecast_Model!Q11-Forecast_Model!S11) -> 32.833333 | Q11: =ABS(Forecast_Model!Q11-Forecast_Model!T11) -> 24.8 | R11: =ABS(Forecast_Model!Q11-Forecast_Model!U11) -> 21.18568 | S11: =ABS(Forecast_Model!Q11-Forecast_Model!V11) -> 20.43083
A12: 11 | B12: 425 | C12: =ABS(Forecast_Model!C12-Forecast_Model!D12) -> 98.666667 | D12: =ABS(Forecast_Model!C12-Forecast_Model!E12) -> 122.16667 | E12: =ABS(Forecast_Model!C12-Forecast_Model!F12) -> 89 | F12: =ABS(Forecast_Model!J12-Forecast_Model!N12) -> 96.005913 | G12: =ABS(Forecast_Model!C12-Forecast_Model!H12) -> 106.17688 | H12: 723 | I12: =ABS(Forecast_Model!J12-Forecast_Model!K12) -> 122.33333 | J12: =ABS(Forecast_Model!J12-Forecast_Model!L12) -> 152.33333 | K12: =ABS(Forecast_Model!J12-Forecast_Model!M12) -> 111.2 | L12: =ABS(Forecast_Model!J12-Forecast_Model!N12) -> 96.005913 | M12: =ABS(Forecast_Model!J12-Forecast_Model!O12) -> 126.15711 | N12: 212 | O12: =ABS(Forecast_Model!Q12-Forecast_Model!R12) -> 48.666667 | P12: =ABS(Forecast_Model!Q12-Forecast_Model!S12) -> 60.833333 | Q12: =ABS(Forecast_Model!Q12-Forecast_Model!T12) -> 43.9 | R12: =ABS(Forecast_Model!Q12-Forecast_Model!U12) -> 38.629976 | S12: =ABS(Forecast_Model!Q12-Forecast_Model!V12) -> 52.367589
A13: 12 | B13: 478 | C13: =ABS(Forecast_Model!C13-Forecast_Model!D13) -> 106.33333 | D13: =ABS(Forecast_Model!C13-Forecast_Model!E13) -> 153.5 | E13: =ABS(Forecast_Model!C13-Forecast_Model!F13) -> 91.9 | F13: =ABS(Forecast_Model!J13-Forecast_Model!N13) -> 119.70414 | G13: =ABS(Forecast_Model!C13-Forecast_Model!H13) -> 155.13043 | H13: 798 | I13: =ABS(Forecast_Model!J13-Forecast_Model!K13) -> 141.66667 | J13: =ABS(Forecast_Model!J13-Forecast_Model!L13) -> 201.33333 | K13: =ABS(Forecast_Model!J13-Forecast_Model!M13) -> 123.9 | L13: =ABS(Forecast_Model!J13-Forecast_Model!N13) -> 119.70414 | M13: =ABS(Forecast_Model!J13-Forecast_Model!O13) -> 196.52174 | N13: 245 | O13: =ABS(Forecast_Model!Q13-Forecast_Model!R13) -> 59.333333 | P13: =ABS(Forecast_Model!Q13-Forecast_Model!S13) -> 83.166667 | Q13: =ABS(Forecast_Model!Q13-Forecast_Model!T13) -> 52.2 | R13: =ABS(Forecast_Model!Q13-Forecast_Model!U13) -> 50.140983 | S13: =ABS(Forecast_Model!Q13-Forecast_Model!V13) -> 83.304348
A14: 13 | B14: 267 | C14: =ABS(Forecast_Model!C14-Forecast_Model!D14) -> 152.66667 | D14: =ABS(Forecast_Model!C14-Forecast_Model!E14) -> 90.833333 | E14: =ABS(Forecast_Model!C14-Forecast_Model!F14) -> 170.7 | F14: =ABS(Forecast_Model!J14-Forecast_Model!N14) -> 84.207102 | G14: =ABS(Forecast_Model!C14-Forecast_Model!H14) -> 59.916008 | H14: 558 | I14: =ABS(Forecast_Model!J14-Forecast_Model!K14) -> 160.33333 | J14: =ABS(Forecast_Model!J14-Forecast_Model!L14) -> 82.666667 | K14: =ABS(Forecast_Model!J14-Forecast_Model!M14) -> 184.7 | L14: =ABS(Forecast_Model!J14-Forecast_Model!N14) -> 84.207102 | M14: =ABS(Forecast_Model!J14-Forecast_Model!O14) -> 48.113636 | N14: 132 | O14: =ABS(Forecast_Model!Q14-Forecast_Model!R14) -> 79.666667 | P14: =ABS(Forecast_Model!Q14-Forecast_Model!S14) -> 47.666667 | Q14: =ABS(Forecast_Model!Q14-Forecast_Model!T14) -> 89.7 | R14: =ABS(Forecast_Model!Q14-Forecast_Model!U14) -> 44.001312 | S14: =ABS(Forecast_Model!Q14-Forecast_Model!V14) -> 31.758893
A15: 14 | B15: 285 | C15: =ABS(Forecast_Model!C15-Forecast_Model!D15) -> 105 | D15: =ABS(Forecast_Model!C15-Forecast_Model!E15) -> 73.166667 | E15: =ABS(Forecast_Model!C15-Forecast_Model!F15) -> 76.9 | F15: =ABS(Forecast_Model!J15-Forecast_Model!N15) -> 49.144972 | G15: =ABS(Forecast_Model!C15-Forecast_Model!H15) -> 45.962451 | H15: 572 | I15: =ABS(Forecast_Model!J15-Forecast_Model!K15) -> 121 | J15: =ABS(Forecast_Model!J15-Forecast_Model!L15) -> 74.833333 | K15: =ABS(Forecast_Model!J15-Forecast_Model!M15) -> 91 | L15: =ABS(Forecast_Model!J15-Forecast_Model!N15) -> 49.144972 | M15: =ABS(Forecast_Model!J15-Forecast_Model!O15) -> 38.749012 | N15: 145 | O15: =ABS(Forecast_Model!Q15-Forecast_Model!R15) -> 51.333333 | P15: =ABS(Forecast_Model!Q15-Forecast_Model!S15) -> 34.833333 | Q15: =ABS(Forecast_Model!Q15-Forecast_Model!T15) -> 36.9 | R15: =ABS(Forecast_Model!Q15-Forecast_Model!U15) -> 21.700918 | S15: =ABS(Forecast_Model!Q15-Forecast_Model!V15) -> 20.822134
A16: 15 | B16: 338 | C16: =ABS(Forecast_Model!C16-Forecast_Model!D16) -> 5.3333333 | D16: =ABS(Forecast_Model!C16-Forecast_Model!E16) -> 19.5 | E16: =ABS(Forecast_Model!C16-Forecast_Model!F16) -> 19.8 | F16: =ABS(Forecast_Model!J16-Forecast_Model!N16) -> 2.2014802 | G16: =ABS(Forecast_Model!C16-Forecast_Model!H16) -> 2.9911067 | H16: 618 | I16: =ABS(Forecast_Model!J16-Forecast_Model!K16) -> 24.666667 | J16: =ABS(Forecast_Model!J16-Forecast_Model!L16) -> 31.5 | K16: =ABS(Forecast_Model!J16-Forecast_Model!M16) -> 5 | L16: =ABS(Forecast_Model!J16-Forecast_Model!N16) -> 2.2014802 | M16: =ABS(Forecast_Model!J16-Forecast_Model!O16) -> 2.6156126 | N16: 168 | O16: =ABS(Forecast_Model!Q16-Forecast_Model!R16) -> 6 | P16: =ABS(Forecast_Model!Q16-Forecast_Model!S16) -> 11.833333 | Q16: =ABS(Forecast_Model!Q16-Forecast_Model!T16) -> 6.9 | R16: =ABS(Forecast_Model!Q16-Forecast_Model!U16) -> 0.90935719 | S16: =ABS(Forecast_Model!Q16-Forecast_Model!V16) -> 0.11462451
A17: 16 | B17: 305 | C17: =ABS(Forecast_Model!C17-Forecast_Model!D17) -> 8.3333333 | D17: =ABS(Forecast_Model!C17-Forecast_Model!E17) -> 53.166667 | E17: =ABS(Forecast_Model!C17-Forecast_Model!F17) -> 2.9 | F17: =ABS(Forecast_Model!J17-Forecast_Model!N17) -> 33.041036 | G17: =ABS(Forecast_Model!C17-Forecast_Model!H17) -> 34.055336 | H17: 573 | I17: =ABS(Forecast_Model!J17-Forecast_Model!K17) -> 9.6666667 | J17: =ABS(Forecast_Model!J17-Forecast_Model!L17) -> 77.5 | K17: =ABS(Forecast_Model!J17-Forecast_Model!M17) -> 19.2 | L17: =ABS(Forecast_Model!J17-Forecast_Model!N17) -> 33.041036 | M17: =ABS(Forecast_Model!J17-Forecast_Model!O17) -> 47.019763 | N17: 153 | O17: =ABS(Forecast_Model!Q17-Forecast_Model!R17) -> 4.6666667 | P17: =ABS(Forecast_Model!Q17-Forecast_Model!S17) -> 27 | Q17: =ABS(Forecast_Model!Q17-Forecast_Model!T17) -> 0.9 | R17: =ABS(Forecast_Model!Q17-Forecast_Model!U17) -> 9.86345 | S17: =ABS(Forecast_Model!Q17-Forecast_Model!V17) -> 16.948617
A18: 17 | B18: 318 | C18: =ABS(Forecast_Model!C18-Forecast_Model!D18) -> 8.6666667 | D18: =ABS(Forecast_Model!C18-Forecast_Model!E18) -> 31.666667 | E18: =ABS(Forecast_Model!C18-Forecast_Model!F18) -> 7.1 | F18: =ABS(Forecast_Model!J18-Forecast_Model!N18) -> 11.928725 | G18: =ABS(Forecast_Model!C18-Forecast_Model!H18) -> 25.101779 | H18: 589 | I18: =ABS(Forecast_Model!J18-Forecast_Model!K18) -> 1.3333333 | J18: =ABS(Forecast_Model!J18-Forecast_Model!L18) -> 51.333333 | K18: =ABS(Forecast_Model!J18-Forecast_Model!M18) -> 2.7 | L18: =ABS(Forecast_Model!J18-Forecast_Model!N18) -> 11.928725 | M18: =ABS(Forecast_Model!J18-Forecast_Model!O18) -> 35.655138 | N18: 159 | O18: =ABS(Forecast_Model!Q18-Forecast_Model!R18) -> 3.6666667 | P18: =ABS(Forecast_Model!Q18-Forecast_Model!S18) -> 16.833333 | Q18: =ABS(Forecast_Model!Q18-Forecast_Model!T18) -> 3.1 | R18: =ABS(Forecast_Model!Q18-Forecast_Model!U18) -> 2.704415 | S18: =ABS(Forecast_Model!Q18-Forecast_Model!V18) -> 13.011858
A19: 18 | B19: 295 | C19: =ABS(Forecast_Model!C19-Forecast_Model!D19) -> 25.333333 | D19: =ABS(Forecast_Model!C19-Forecast_Model!E19) -> 36.833333 | E19: =ABS(Forecast_Model!C19-Forecast_Model!F19) -> 23.1 | F19: =ABS(Forecast_Model!J19-Forecast_Model!N19) -> 27.950108 | G19: =ABS(Forecast_Model!C19-Forecast_Model!H19) -> 52.148221 | H19: 561 | I19: =ABS(Forecast_Model!J19-Forecast_Model!K19) -> 32.333333 | J19: =ABS(Forecast_Model!J19-Forecast_Model!L19) -> 57 | K19: =ABS(Forecast_Model!J19-Forecast_Model!M19) -> 29 | L19: =ABS(Forecast_Model!J19-Forecast_Model!N19) -> 27.950108 | M19: =ABS(Forecast_Model!J19-Forecast_Model!O19) -> 68.290514 | N19: 147 | O19: =ABS(Forecast_Model!Q19-Forecast_Model!R19) -> 13 | P19: =ABS(Forecast_Model!Q19-Forecast_Model!S19) -> 20 | Q19: =ABS(Forecast_Model!Q19-Forecast_Model!T19) -> 12 | R19: =ABS(Forecast_Model!Q19-Forecast_Model!U19) -> 10.29309 | S19: =ABS(Forecast_Model!Q19-Forecast_Model!V19) -> 27.075099
... A25: 24 | B25: 512 | C25: =ABS(Forecast_Model!C25-Forecast_Model!D25) -> 113.33333 | D25: =ABS(Forecast_Model!C25-Forecast_Model!E25) -> 165.16667 | E25: =ABS(Forecast_Model!C25-Forecast_Model!F25) -> 97.8 | F25: =ABS(Forecast_Model!J25-Forecast_Model!N25) -> 120.37914 | G25: =ABS(Forecast_Model!C25-Forecast_Model!H25) -> 140.57312 | H25: 834 | I25: =ABS(Forecast_Model!J25-Forecast_Model!K25) -> 142.33333 | J25: =ABS(Forecast_Model!J25-Forecast_Model!L25) -> 206.5 | K25: =ABS(Forecast_Model!J25-Forecast_Model!M25) -> 123.6 | L25: =ABS(Forecast_Model!J25-Forecast_Model!N25) -> 120.37914 | M25: =ABS(Forecast_Model!J25-Forecast_Model!O25) -> 176.89723 | N25: 263 | O25: =ABS(Forecast_Model!Q25-Forecast_Model!R25) -> 63.333333 | P25: =ABS(Forecast_Model!Q25-Forecast_Model!S25) -> 89.166667 | Q25: =ABS(Forecast_Model!Q25-Forecast_Model!T25) -> 55.6 | R25: =ABS(Forecast_Model!Q25-Forecast_Model!U25) -> 52.725484 | S25: =ABS(Forecast_Model!Q25-Forecast_Model!V25) -> 76.545455
A30: Metric | B30: 3M_MA(SKU001) | C30: 6M_MA(SKU001) | D30: WMA(SKU001) | E30: Exp_Smooth(SKU001) | F30: Linear_Reg(SKU001) | G30: 3M_MA(SKU002) | H30: 6M_MA(SKU002) | I30: WMA(SKU002) | J30: Exp_Smooth(SKU002) | K30: Linear_Reg(SKU002) | L30: 3M_MA(SKU003) | M30: 6M_MA(SKU003) | N30: WMA(SKU003) | O30: Exp_Smooth(SKU003) | P30: Linear_Reg(SKU003)
A31: MAE | B31: {=AVERAGE(ABS(Forecast_Model!C5:C24-Forecast_Model!D5:D24))} -> 48.283333 | C31: {=AVERAGE(ABS(Forecast_Model!C8:C24-Forecast_Model!E8:E24))} -> 58.205882 | D31: {=AVERAGE(ABS(Forecast_Model!C5:C24-Forecast_Model!F5:F24))} -> 44.52 | E31: {=AVERAGE(ABS(Forecast_Model!C2:C24-Forecast_Model!G2:G24))} -> 31.275354 | F31: {=AVERAGE(ABS(Forecast_Model!C2:C24-Forecast_Model!H2:H24))} -> 40.180959 | G31: {=AVERAGE(ABS(Forecast_Model!J5:J24-Forecast_Model!K5:K24))} -> 59.466667 | H31: {=AVERAGE(ABS(Forecast_Model!J8:J24-Forecast_Model!L8:L24))} -> 74.107843 | I31: {=AVERAGE(ABS(Forecast_Model!J5:J24-Forecast_Model!M5:M24))} -> 55.47 | J31: {=AVERAGE(ABS(Forecast_Model!J2:J24-Forecast_Model!N2:N24))} -> 37.439639 | K31: {=AVERAGE(ABS(Forecast_Model!J2:J24-Forecast_Model!O2:O24))} -> 48.022512 | L31: {=AVERAGE(ABS(Forecast_Model!Q5:Q24-Forecast_Model!R5:R24))} -> 24.9 | M31: {=AVERAGE(ABS(Forecast_Model!Q8:Q24-Forecast_Model!S8:S24))} -> 30.098039 | N31: {=AVERAGE(ABS(Forecast_Model!Q5:Q24-Forecast_Model!T5:T24))} -> 22.78 | O31: {=AVERAGE(ABS(Forecast_Model!Q2:Q24-Forecast_Model!U2:U24))} -> 15.936402 | P31: {=AVERAGE(ABS(Forecast_Model!Q2:Q24-Forecast_Model!V2:V24))} -> 20.4011
A32: MAPE | B32: {=AVERAGE(ABS((Forecast_Model!C5:C24-Forecast_Model!D5:D24)/Forecast_Model!C5:C24))*100} -> 14.18857 | C32: {=AVERAGE(ABS((Forecast_Model!C8:C24-Forecast_Model!E8:E24)/Forecast_Model!C8:C24))*100} -> 16.218721 | D32: {=AVERAGE(ABS((Forecast_Model!C5:C24-Forecast_Model!F5:F24)/Forecast_Model!C5:C24))*100} -> 13.184221 | E32: {=AVERAGE(ABS((Forecast_Model!C2:C24-Forecast_Model!G2:G24)/Forecast_Model!C2:C24))*100} -> 9.06232 | F32: {=AVERAGE(ABS((Forecast_Model!C2:C24-Forecast_Model!H2:H24)/Forecast_Model!C2:C24))*100} -> 11.869966 | G32: {=AVERAGE(ABS((Forecast_Model!J5:J24-Forecast_Model!K5:K24)/Forecast_Model!J5:J24))*100} -> 9.3458763 | H32: {=AVERAGE(ABS((Forecast_Model!J8:J24-Forecast_Model!L8:L24)/Forecast_Model!J8:J24))*100} -> 11.341955 | I32: {=AVERAGE(ABS((Forecast_Model!J5:J24-Forecast_Model!M5:M24)/Forecast_Model!J5:J24))*100} -> 8.792429 | J32: {=AVERAGE(ABS((Forecast_Model!J2:J24-Forecast_Model!N2:N24)/Forecast_Model!J2:J24))*100} -> 5.8432721 | K32: {=AVERAGE(ABS((Forecast_Model!J2:J24-Forecast_Model!O2:O24)/Forecast_Model!J2:J24))*100} -> 7.6161788 | L32: {=AVERAGE(ABS((Forecast_Model!Q5:Q24-Forecast_Model!R5:R24)/Forecast_Model!Q5:Q24))*100} -> 14.613265 | M32: {=AVERAGE(ABS((Forecast_Model!Q8:Q24-Forecast_Model!S8:S24)/Forecast_Model!Q8:Q24))*100} -> 16.741407 | N32: {=AVERAGE(ABS((Forecast_Model!Q5:Q24-Forecast_Model!T5:T24)/Forecast_Model!Q5:Q24))*100} -> 13.495788 | O32: {=AVERAGE(ABS((Forecast_Model!Q2:Q24-Forecast_Model!U2:U24)/Forecast_Model!Q2:Q24))*100} -> 9.2160095 | P32: {=AVERAGE(ABS((Forecast_Model!Q2:Q24-Forecast_Model!V2:V24)/Forecast_Model!Q2:Q24))*100} -> 12.005089
A33: RMSE | B33: =SQRT(SUMPRODUCT((Forecast_Model!C5:C24-Forecast_Model!D5:D24)^2/COUNT(Forecast_Model!D5:D24))) -> 65.005769 | C33: =SQRT(SUMPRODUCT((Forecast_Model!C8:C24-Forecast_Model!E8:E24)^2/COUNT(Forecast_Model!E8:E24))) -> 72.636743 | D33: =SQRT(SUMPRODUCT((Forecast_Model!C5:C24-Forecast_Model!F5:F24)^2/COUNT(Forecast_Model!F5:F24))) -> 61.333645 | E33: =SQRT(SUMPRODUCT((Forecast_Model!C2:C24-Forecast_Model!G2:G24)^2/COUNT(Forecast_Model!G2:G24))) -> 41.925468 | F33: =SQRT(SUMPRODUCT((Forecast_Model!C2:C24-Forecast_Model!H2:H24)^2/COUNT(Forecast_Model!H2:H24))) -> 54.038 | G33: =SQRT(SUMPRODUCT((Forecast_Model!J5:J24-Forecast_Model!K5:K24)^2/COUNT(Forecast_Model!K5:K24))) -> 77.665308 | H33: =SQRT(SUMPRODUCT((Forecast_Model!J8:J24-Forecast_Model!L8:L24)^2/COUNT(Forecast_Model!L8:L24))) -> 90.53576 | I33: =SQRT(SUMPRODUCT((Forecast_Model!J5:J24-Forecast_Model!M5:M24)^2/COUNT(Forecast_Model!M5:M24))) -> 73.183584 | J33: =SQRT(SUMPRODUCT((Forecast_Model!J2:J24-Forecast_Model!N2:N24)^2/COUNT(Forecast_Model!N2:N24))) -> 49.985341 | K33: =SQRT(SUMPRODUCT((Forecast_Model!J2:J24-Forecast_Model!O2:O24)^2/COUNT(Forecast_Model!O2:O24))) -> 65.723794 | L33: =SQRT(SUMPRODUCT((Forecast_Model!Q5:Q24-Forecast_Model!R5:R24)^2/COUNT(Forecast_Model!R5:R24))) -> 33.314161 | M33: =SQRT(SUMPRODUCT((Forecast_Model!Q8:Q24-Forecast_Model!S8:S24)^2/COUNT(Forecast_Model!S8:S24))) -> 37.371698 | N33: =SQRT(SUMPRODUCT((Forecast_Model!Q5:Q24-Forecast_Model!T5:T24)^2/COUNT(Forecast_Model!T5:T24))) -> 31.60511 | O33: =SQRT(SUMPRODUCT((Forecast_Model!Q2:Q24-Forecast_Model!U2:U24)^2/COUNT(Forecast_Model!U2:U24))) -> 21.502686 | P33: =SQRT(SUMPRODUCT((Forecast_Model!Q2:Q24-Forecast_Model!V2:V24)^2/COUNT(Forecast_Model!V2:V24))) -> 27.729142
A34: Forecast Bias | B34: {=SUM(Forecast_Model!C5:C24-Forecast_Model!D5:D24)/COUNT(Forecast_Model!D5:D24)} -> 12.883333 | C34: {=SUM(Forecast_Model!C8:C24-Forecast_Model!E8:E24)/COUNT(Forecast_Model!E8:E24)} -> 18.166667 | D34: {=SUM(Forecast_Model!C5:C24-Forecast_Model!F5:F24)/COUNT(Forecast_Model!F5:F24)} -> 11.18 | E34: {=SUM(Forecast_Model!C2:C24-Forecast_Model!G2:G24)/COUNT(Forecast_Model!G2:G24)} -> 13.136203 | F34: {=SUM(Forecast_Model!C2:C24-Forecast_Model!H2:H24)/COUNT(Forecast_Model!H2:H24)} -> 0 | G34: {=SUM(Forecast_Model!J5:J24-Forecast_Model!K5:K24)/COUNT(Forecast_Model!K5:K24)} -> 14.533333 | H34: {=SUM(Forecast_Model!J8:J24-Forecast_Model!L8:L24)/COUNT(Forecast_Model!L8:L24)} -> 22.362745 | I34: {=SUM(Forecast_Model!J5:J24-Forecast_Model!M5:M24)/COUNT(Forecast_Model!M5:M24)} -> 12.78 | J34: {=SUM(Forecast_Model!J2:J24-Forecast_Model!N2:N24)/COUNT(Forecast_Model!N2:N24)} -> 13.191428 | K34: {=SUM(Forecast_Model!J2:J24-Forecast_Model!O2:O24)/COUNT(Forecast_Model!O2:O24)} -> 0 | L34: {=SUM(Forecast_Model!Q5:Q24-Forecast_Model!R5:R24)/COUNT(Forecast_Model!R5:R24)} -> 6.4666667 | M34: {=SUM(Forecast_Model!Q8:Q24-Forecast_Model!S8:S24)/COUNT(Forecast_Model!S8:S24)} -> 9.2745098 | N34: {=SUM(Forecast_Model!Q5:Q24-Forecast_Model!T5:T24)/COUNT(Forecast_Model!T5:T24)} -> 5.61 | O34: {=SUM(Forecast_Model!Q2:Q24-Forecast_Model!U2)/COUNT(Forecast_Model!U2:U24)} -> 38.695652 | P34: {=SUM(Forecast_Model!Q2:Q24-Forecast_Model!V2:V24)/COUNT(Forecast_Model!V2:V24)} -> 0
F978: Date | G978: 3M_MA_Error(SKU001) | H978: 6M_MA_Error(SKU001) | I978: WMA_Error(SKU001) | J978: Exp_Error(SKU001) | K978: Reg_Error(SKU001) | L978: 3M_MA_Error(SKU001) | M978: 6M_MA_Error(SKU001) | N978: WMA_Error(SKU001) | O978: Exp_Error(SKU001) | P978: Reg_Error(SKU001) | Q978: ABS_Pct_Error(SKU001)
F979: 44927 | J979: 0 | K979: 33.358696 | P979: =ABS(G979-K979) -> 33.358696
F980: 44958 | J980: 11.2 | K980: 14.405138 | P980: =ABS(G980-K980) -> 14.405138
F981: 44986 | J981: 36.54 | K981: 25.548419 | O981: =ABS(G981-J981) -> 36.54 | P981: =ABS(G981-K981) -> 25.548419
F982: 45017 | G982: 12 | I982: 1.6 | J982: 5.222 | K982: 3.4980237 | L982: =ABS(G982-H982) -> 12 | N982: =ABS(G982-I982) -> 10.4 | O982: =ABS(G982-J982) -> 6.778 | P982: =ABS(G982-K982) -> 8.5019763 | Q982: =ABS((G982-I982)/G982)*100 -> 86.666667
F983: 45047 | G983: 6 | I983: 4.3 | J983: 11.7446 | K983: 0.4555336 | L983: =ABS(G983-H983) -> 6 | N983: =ABS(G983-I983) -> 1.7 | O983: =ABS(G983-J983) -> 5.7446 | P983: =ABS(G983-K983) -> 5.5444664 | Q983: =ABS((G983-I983)/G983)*100 -> 28.333333
F984: 45078 | G984: 20 | I984: 18 | J984: 14.87878 | K984: 20.590909 | L984: =ABS(G984-H984) -> 20 | N984: =ABS(G984-I984) -> 2 | O984: =ABS(G984-J984) -> 5.12122 | P984: =ABS(G984-K984) -> 0.59090909 | Q984: =ABS((G984-I984)/G984)*100 -> 10
A985: Metric | B985: MAPE | C985: RMSE | D985: Forecast Bias | E985: MAE | F985: 45108 | G985: 21.666667 | H985: 15.833333 | I985: 19.9 | J985: 19.515146 | K985: 37.637352 | L985: =ABS(G985-H985) -> 5.8333333 | M985: =ABS(G985-H985) -> 5.8333333 | N985: =ABS(G985-I985) -> 1.7666667 | O985: =ABS(G985-J985) -> 2.1515207 | P985: =ABS(G985-K985) -> 15.970685 | Q985: =ABS((G985-I985)/G985)*100 -> 8.1538462
A986: 3M_MA(SKU001) | B986: 14.18857 | C986: 65.005769 | D986: 12.883333 | E986: 48.283333 | F986: 45139 | G986: 9.6666667 | H986: 4.8333333 | I986: 14.1 | J986: 10.839398 | K986: 17.683794 | L986: =ABS(G986-H986) -> 4.8333333 | M986: =ABS(G986-H986) -> 4.8333333 | N986: =ABS(G986-I986) -> 4.4333333 | O986: =ABS(G986-J986) -> 1.1727311 | P986: =ABS(G986-K986) -> 8.0171278 | Q986: =ABS((G986-I986)/G986)*100 -> 45.862069
A987: 6M_MA(SKU001) | B987: 16.218721 | C987: 72.636743 | D987: 18.166667 | E987: 58.205882 | F987: 45170 | G987: 56.666667 | H987: 46.333333 | I987: 54.4 | J987: 46.787578 | K987: 23.269763 | L987: =ABS(G987-H987) -> 10.333333 | M987: =ABS(G987-H987) -> 10.333333 | N987: =ABS(G987-I987) -> 2.2666667 | O987: =ABS(G987-J987) -> 9.8790882 | P987: =ABS(G987-K987) -> 33.396904 | Q987: =ABS((G987-I987)/G987)*100 -> 4
A988: WMA(SKU001) | B988: 13.184221 | C988: 61.333645 | D988: 11.18 | E988: 44.52 | F988: 45200 | G988: 60 | H988: 64.666667 | I988: 49.3 | J988: 48.151305 | K988: 41.22332 | L988: =ABS(G988-H988) -> 4.6666667 | M988: =ABS(G988-H988) -> 4.6666667 | N988: =ABS(G988-I988) -> 10.7 | O988: =ABS(G988-J988) -> 11.848695 | P988: =ABS(G988-K988) -> 18.77668 | Q988: =ABS((G988-I988)/G988)*100 -> 17.833333
A989: Exp_Smooth(SKU001) | B989: 9.06232 | C989: 41.925468 | D989: 13.136203 | E989: 31.275354 | F989: 45231 | G989: 98.666667 | H989: 122.16667 | I989: 89 | J989: 96.005913 | K989: 106.17688 | L989: =ABS(G989-H989) -> 23.5 | M989: =ABS(G989-H989) -> 23.5 | N989: =ABS(G989-I989) -> 9.6666667 | O989: =ABS(G989-J989) -> 2.6607532 | P989: =ABS(G989-K989) -> 7.5102108 | Q989: =ABS((G989-I989)/G989)*100 -> 9.7972973
A990: Linear_Reg(SKU001) | B990: 11.869966 | C990: 54.038 | D990: -5.9314872e-14 | E990: 40.180959 | F990: 45261 | G990: 106.33333 | H990: 153.5 | I990: 91.9 | J990: 119.70414 | K990: 155.13043 | L990: =ABS(G990-H990) -> 47.166667 | M990: =ABS(G990-H990) -> 47.166667 | N990: =ABS(G990-I990) -> 14.433333 | O990: =ABS(G990-J990) -> 13.370806 | P990: =ABS(G990-K990) -> 48.797101 | Q990: =ABS((G990-I990)/G990)*100 -> 13.573668
A991: 3M_MA(SKU002) | B991: 9.3458763 | C991: 77.665308 | D991: 14.533333 | E991: 59.466667 | F991: 45292 | G991: 152.66667 | H991: 90.833333 | I991: 170.7 | J991: 84.207102 | K991: 59.916008 | L991: =ABS(G991-H991) -> 61.833333 | M991: =ABS(G991-H991) -> 61.833333 | N991: =ABS(G991-I991) -> 18.033333 | O991: =ABS(G991-J991) -> 68.459564 | P991: =ABS(G991-K991) -> 92.750659 | Q991: =ABS((G991-I991)/G991)*100 -> 11.812227
A992: 6M_MA(SKU002) | B992: 11.341955 | C992: 90.53576 | D992: 22.362745 | E992: 74.107843 | F992: 45323 | G992: 105 | H992: 73.166667 | I992: 76.9 | J992: 49.144972 | K992: 45.962451 | L992: =ABS(G992-H992) -> 31.833333 | M992: =ABS(G992-H992) -> 31.833333 | N992: =ABS(G992-I992) -> 28.1 | O992: =ABS(G992-J992) -> 55.855028 | P992: =ABS(G992-K992) -> 59.037549 | Q992: =ABS((G992-I992)/G992)*100 -> 26.761905
...

Sheet Dashboard
C2: Best Method | E2: Lowest MAPE | G2: Forecast Accuracy | I2: SKUs Analyzed
C3: Weighted Moving Average | E3: 5.61 | G3: =100-MIN(Accuracy_Metrics!B32:P32) -> 94.156728 | I3: 3
